<?xml version="1.0" ?>
<!-- =================================================================================== -->
<!-- |    This document was autogenerated by xacro from 6dof.urdf.xacro                | -->
<!-- |    EDITING THIS FILE BY HAND IS NOT RECOMMENDED                                 | -->
<!-- =================================================================================== -->
<robot name="sainsmart" xmlns:xacro="http://ros.org/wiki/xacro">
  <!-- arm properties -->
  <!-- Materials -->
  <material name="blue">
    <color rgba="0 0 0.8 1"/>
  </material>
  <material name="white">
    <color rgba="1 1 1 1"/>
  </material>
  <!-- Macros -->
  <!-- Wrist -->
  <link name="interface">
    <visual>
      <geometry>
        <cylinder length="0.03" radius="0.02"/>
      </geometry>
      <material name="blue"/>
      <origin rpy="1.57075 0 0" xyz="0 0 0"/>
    </visual>
    <collision>
      <geometry>
        <cylinder length="0.03" radius="0.02"/>
      </geometry>
    </collision>
    <inertial>
      <mass value="10"/>
      <inertia ixx="1.0" ixy="0.0" ixz="0.0" iyy="1.0" iyz="0.0" izz="1.0"/>
    </inertial>
  </link>
  <joint name="interface" type="revolute">
    <axis rpy="1.57075 0 0" xyz="0 1 0"/>
    <limit effort="0.0001" lower="-2.2" upper="1.7" velocity="0.0001"/>
    <parent link="wrist"/>
    <child link="interface"/>
    <origin rpy="0 0 0" xyz="0 0.02 0"/>
  </joint>
  <!-- Wrist -->
  <link name="wrist">
    <visual>
      <geometry>
        <cylinder length="0.03" radius="0.02"/>
      </geometry>
      <material name="blue"/>
      <origin rpy="0 1.57075 0" xyz=" 0 0 0"/>
    </visual>
    <collision>
      <geometry>
        <cylinder length="0.03" radius="0.02"/>
      </geometry>
    </collision>
    <inertial>
      <mass value="10"/>
      <inertia ixx="1.0" ixy="0.0" ixz="0.0" iyy="1.0" iyz="0.0" izz="1.0"/>
    </inertial>
  </link>
  <joint name="wrist" type="continuous">
    <axis rpy="0 0.785375 0" xyz="1 0 0"/>
    <parent link="forearm"/>
    <child link="wrist"/>
    <origin rpy="0 0 0" xyz="0 0.15 0"/>
  </joint>
  <!-- Forearm -->
  <link name="forearm">
    <visual>
      <geometry>
        <cylinder length="0.15" radius="0.02"/>
      </geometry>
      <material name="blue"/>
      <origin rpy="1.57075 0 0" xyz="0 0.075 0"/>
    </visual>
    <collision>
      <geometry>
        <cylinder length="0.15" radius="0.02"/>
      </geometry>
    </collision>
    <inertial>
      <mass value="10"/>
      <inertia ixx="1.0" ixy="0.0" ixz="0.0" iyy="1.0" iyz="0.0" izz="1.0"/>
    </inertial>
  </link>
  <joint name="roll" type="continuous">
    <axis rpy="0 0 0" xyz=" 0 1 0"/>
    <parent link="elbow"/>
    <child link="forearm"/>
    <origin rpy="0 0 0" xyz="0 0 0"/>
  </joint>
  <link name="elbow">
    <visual>
      <geometry>
        <box size="0.05 0.05 0.07"/>
      </geometry>
      <material name="blue"/>
      <origin rpy="0 0 0" xyz="0 0 0"/>
    </visual>
    <collision>
      <geometry>
        <box size="0.1 0.1 0.1"/>
      </geometry>
    </collision>
    <inertial>
      <mass value="10"/>
      <inertia ixx="1.0" ixy="0.0" ixz="0.0" iyy="1.0" iyz="0.0" izz="1.0"/>
    </inertial>
  </link>
  <joint name="eblow" type="continuous">
    <axis rpy="0 0 0" xyz="1 0 0"/>
    <parent link="base_arm"/>
    <child link="elbow"/>
    <origin rpy="0 0 0" xyz="0 0 0.2"/>
  </joint>
  <link name="base_arm">
    <visual>
      <geometry>
        <cylinder length="0.2" radius="0.02"/>
      </geometry>
      <material name="blue"/>
      <origin rpy="0 0 0" xyz="0.02 0 0.1"/>
    </visual>
    <collision>
      <geometry>
        <cylinder length="0.06" radius="0.05"/>
      </geometry>
    </collision>
    <inertial>
      <mass value="10"/>
      <inertia ixx="1.0" ixy="0.0" ixz="0.0" iyy="1.0" iyz="0.0" izz="1.0"/>
    </inertial>
  </link>
  <joint name="shoulder" type="continuous">
    <axis rpy="0 0 0" xyz="1 0 0"/>
    <parent link="base_arm_support"/>
    <child link="base_arm"/>
    <origin rpy="0 0 0" xyz="0 0 0.07"/>
  </joint>
  <link name="base_arm_support">
    <visual>
      <geometry>
        <box size="0.01 0.1 0.07"/>
      </geometry>
      <material name="blue"/>
      <origin rpy="0 0 0" xyz="0 0 0.07"/>
    </visual>
    <collision>
      <geometry>
        <box size="0.1 0.1 0.1"/>
      </geometry>
    </collision>
    <inertial>
      <mass value="10"/>
      <inertia ixx="1.0" ixy="0.0" ixz="0.0" iyy="1.0" iyz="0.0" izz="1.0"/>
    </inertial>
  </link>
  <joint name="support" type="fixed">
    <axis rpy="0 0 0" xyz="0 0 1"/>
    <parent link="main_base"/>
    <child link="base_arm_support"/>
    <origin rpy="0 0 0" xyz="0 0 0"/>
  </joint>
  <link name="main_base">
    <visual>
      <geometry>
        <cylinder length="0.06" radius="0.05"/>
      </geometry>
      <material name="blue"/>
      <origin rpy="0 0 0" xyz="0 0 0.035"/>
    </visual>
    <collision>
      <geometry>
        <cylinder length="0.06" radius="0.05"/>
      </geometry>
    </collision>
    <inertial>
      <mass value="10"/>
      <inertia ixx="1.0" ixy="0.0" ixz="0.0" iyy="1.0" iyz="0.0" izz="1.0"/>
    </inertial>
  </link>
  <link name="base_link">
    <visual>
      <geometry>
        <box size="0.1 0.1 0.01"/>
      </geometry>
      <material name="blue"/>
      <origin rpy="0 0 0" xyz="0 0 0"/>
    </visual>
    <collision>
      <geometry>
        <box size="0.1 0.1 0.1"/>
      </geometry>
    </collision>
    <inertial>
      <origin xyz="0 0 0" rpy="0 0 0"/>
      <mass value="10"/>
      <inertia ixx="1.0" ixy="0.0" ixz="0.0" iyy="1.0" iyz="0.0" izz="1.0"/>
    </inertial>
  </link>
  <joint name="bottom" type="continuous">
    <axis rpy="0 0 0" xyz="0 0 1"/>
    <parent link="base_link"/>
    <child link="main_base"/>
    <origin rpy="0 0 0" xyz="0 0 0"/>
  </joint>
</robot>
