<?xml version="1.0"?>

<robot name="new">

    <!-- Materials -->

    <material name="blue">
        <color rgba="0 0 0.8 1"/>
    </material>

    <material name="white">
        <color rgba="1 1 1 1"/>
    </material>

    <!-- Wrist -->

    <link name="interface">
        <visual>
            <geometry>
                <cylinder radius="0.02" length="0.03"/>
            </geometry>
            <material name="blue"/>
            <origin xyz=" 0 0 0" rpy="1.57079632679 0 0"/>
        </visual>
        <collision>
            <geometry>
                <cylinder radius="0.02" length="0.03"/>
            </geometry>
            <origin xyz=" 0 0 0" rpy="1.57079632679 0 0"/>
        </collision>
        <inertial>
            <mass value="10" />
            <inertia ixx="1.0" ixy="0.0" ixz="0.0" iyy="1.0" iyz="0.0" izz="1.0" />
        </inertial>
    </link>

    <joint name="interface" type="revolute">
        <axis xyz="0 1 0" rpy="1.57079632679 0 0" />
        <limit effort="0.0001" velocity="0.0001" lower="-2.2" upper="1.7"/>
        <parent link="wrist"/>
        <child link="interface"/>
        <origin xyz="0 0.02 0" rpy="0 0 0"/>
    </joint>

    <transmission name="interface_trans">
        <type>transmission_interface/SimpleTransmission</type>
        <actuator name="$interface_motor">
            <mechanicalReduction>1</mechanicalReduction>
        </actuator>
        <joint name="interface">
            <hardwareInterface>PositionJointInterface</hardwareInterface>
        </joint>
    </transmission>

    <!-- Wrist -->

    <link name="wrist">
        <visual>
            <geometry>
                <cylinder radius="0.02" length="0.03"/>
            </geometry>
            <material name="blue"/>
            <origin xyz=" 0 0 0" rpy="0 1.57079632679 0"/>
        </visual>
        <inertial>
            <mass value="10" />
            <inertia ixx="1.0" ixy="0.0" ixz="0.0" iyy="1.0" iyz="0.0" izz="1.0" />
        </inertial>
    </link>

    <joint name="wrist" type="revolute">
        <limit effort="0.0001" velocity="0.0001" lower="-1.56" upper="1.56"/>
        <axis xyz="1 0 0" rpy="0 0.78539816339 0" />
        <parent link="forearm"/>
        <child link="wrist"/>
        <origin xyz="0 0.15 0" rpy="0 0 0"/>
    </joint>

    <!-- Forearm -->

    <link name="forearm">
        <visual>
            <geometry>
                <cylinder radius="0.02" length="0.15"/>
            </geometry>
            <material name="blue"/>
            <origin xyz="0 0.075 0" rpy="1.57079632679 0 0"/>
        </visual>
        <collision>
            <geometry>
                <cylinder radius="0.02" length="0.15"/>
            </geometry>
            <origin xyz="0 0.075 0" rpy="1.57079632679 0 0"/>
        </collision>
        <inertial>
            <mass value="10" />
            <inertia ixx="1.0" ixy="0.0" ixz="0.0" iyy="1.0" iyz="0.0" izz="1.0" />
        </inertial>
    </link>

    <joint name="roll" type="revolute">
        <limit effort="0.0001" velocity="0.0001" lower="-1.56" upper="2.0"/>
        <axis xyz="0 1 0" rpy="0 0 0" />
        <parent link="elbow"/>
        <child link="forearm"/>
        <origin xyz="0 0 0.026" rpy="0 0 0"/>
    </joint>

    <!-- Elbow -->

    <link name="elbow">
        <visual>
            <geometry>
                <box size="0.05 0.05 0.07"/>
            </geometry>
            <material name="blue"/>
            <origin xyz="0 0 0.035"/>
        </visual>
        <inertial>
            <mass value="10" />
            <inertia ixx="1.0" ixy="0.0" ixz="0.0" iyy="1.0" iyz="0.0" izz="1.0" />
        </inertial>
    </link>

    <joint name="elbow" type="revolute">
        <limit effort="0.0001" velocity="0.0001" lower="-1.3" upper="0.5"/>
        <axis xyz="1 0 0" rpy="0 0 0" />
        <parent link="base_arm"/>
        <child link="elbow"/>
        <origin xyz="0 0 0.127" rpy="0 0 0"/>
    </joint>

    <!-- Base Arm -->
   
    <link name="base_arm">
        <visual>
            <geometry>
                <cylinder radius="0.02" length="0.127"/>
            </geometry>
            <material name="blue"/>
            <origin xyz="0 0 0.0635"/>
        </visual>
        <collision>
            <geometry>
                <cylinder radius="0.02" length="0.127"/>
            </geometry>
            <origin xyz="0 0 0.0635"/>
        </collision>
        <inertial>
            <mass value="10" />
            <inertia ixx="1.0" ixy="0.0" ixz="0.0" iyy="1.0" iyz="0.0" izz="1.0" />
        </inertial>
    </link>

    <joint name="shoulder" type="revolute">
        <limit effort="0.0001" velocity="0.0001" lower="-2.0" upper="1.2"/>
        <axis xyz="1 0 0" rpy="0 0 0" />
        <parent link="base_arm_support"/>
        <child link="base_arm"/>
        <origin xyz="0 0.03 -0.01" rpy="0 0 0"/>
    </joint>

    <link name="base_arm_support">
        <visual>
            <geometry>
                <box size="0.01 0.1 0.07"/>
            </geometry>
            <material name="blue"/>
            <origin xyz="0 0 0"/>
        </visual>
        <collision>
            <geometry>
                <box size="0.01 0.1 0.07"/>
            </geometry>
        </collision>
        <inertial>
            <mass value="10" />
            <inertia ixx="1.0" ixy="0.0" ixz="0.0" iyy="1.0" iyz="0.0" izz="1.0" />
        </inertial>
    </link>
    
    <joint name="support" type="fixed">
        <axis xyz="0 0 1" rpy="0 0 0" />
        <parent link="main_base"/>
        <child link="base_arm_support"/>
        <origin xyz="0 0 0.06" rpy="0 0 0"/>
    </joint>

    <link name="main_base">
        <visual>
            <geometry>
                <cylinder radius="0.05" length="0.05"/>
            </geometry>
            <material name="blue"/>
            <origin xyz="0 0 0"/>
        </visual>
        <collision>
            <geometry>
                <cylinder radius="0.05" length="0.05"/>
            </geometry>
        </collision>
        <inertial>
            <mass value="10" />
            <inertia ixx="1.0" ixy="0.0" ixz="0.0" iyy="1.0" iyz="0.0" izz="1.0" />
        </inertial>
    </link>

    <link name="base_link">
        <visual>
            <geometry>
                <box size="0.1 0.1 0.015"/>
            </geometry>
            <material name="blue"/>
            <origin xyz="0 0 0"/>
        </visual>
        <collision>
            <geometry>
                <box size="0.1 0.1 0.015"/>
            </geometry>
        </collision>
        <inertial>
            <mass value="10" />
            <inertia ixx="1.0" ixy="0.0" ixz="0.0" iyy="1.0" iyz="0.0" izz="1.0" />
        </inertial>
    </link>

    <joint name="bottom" type="revolute">
        <limit effort="0.0001" velocity="0.0001" lower="-1.56" upper="1.56"/>
        <axis xyz="0 0 1" rpy="0 0 0" />
        <parent link="base_link"/>
        <child link="main_base"/>
        <origin xyz="0 0 0.03275" rpy="0 0 0"/>
    </joint>

    <link name="world" />

    <joint name="base_to_world" type="fixed">
        <parent link="world" />
        <child link="base_link" />
    </joint>

</robot>


